2024-11-25 19:17:30 - ERROR - [domains_check_MT.py:51] - HTTP Request error for microsoft.com: HTTPConnectionPool(host='microsoft.com', port=80): Read timed out. (read timeout=1)
None
2024-11-25 19:17:32 - ERROR - [domains_check_MT.py:88] - SSL check error for miit.gov.cn: [Errno 11001] getaddrinfo failed
None
2024-11-25 19:17:32 - ERROR - [domains_check_MT.py:51] - HTTP Request error for miit.gov.cn: HTTPConnectionPool(host='miit.gov.cn', port=80): Max retries exceeded with url: / (Caused by NameResolutionError("<urllib3.connection.HTTPConnection object at 0x00000178E0E50590>: Failed to resolve 'miit.gov.cn' ([Errno 11001] getaddrinfo failed)"))
None
2024-11-25 19:17:32 - ERROR - [domains_check_MT.py:51] - HTTP Request error for nih.gov: ('Connection aborted.', RemoteDisconnected('Remote end closed connection without response'))
None
2024-11-25 19:17:34 - ERROR - [domains_check_MT.py:88] - SSL check error for wixsite.com: [Errno 11001] getaddrinfo failed
None
2024-11-25 19:17:34 - ERROR - [domains_check_MT.py:51] - HTTP Request error for wixsite.com: HTTPConnectionPool(host='wixsite.com', port=80): Max retries exceeded with url: / (Caused by NameResolutionError("<urllib3.connection.HTTPConnection object at 0x00000178E0EBAA20>: Failed to resolve 'wixsite.com' ([Errno 11001] getaddrinfo failed)"))
None
2024-11-25 19:17:34 - ERROR - [domains_check_MT.py:88] - SSL check error for vk.com: [SSL: CERTIFICATE_VERIFY_FAILED] certificate verify failed: self-signed certificate in certificate chain (_ssl.c:1000)
None
2024-11-25 19:17:35 - ERROR - [domains_check_MT.py:51] - HTTP Request error for f5.com: HTTPSConnectionPool(host='www.f5.com', port=443): Read timed out. (read timeout=1)
None
2024-11-25 19:17:35 - ERROR - [domains_check_MT.py:88] - SSL check error for youtube-nocookie.com: [SSL: CERTIFICATE_VERIFY_FAILED] certificate verify failed: Hostname mismatch, certificate is not valid for 'youtube-nocookie.com'. (_ssl.c:1000)
None
2024-11-25 19:17:35 - ERROR - [domains_check_MT.py:51] - HTTP Request error for youtube-nocookie.com: HTTPSConnectionPool(host='youtube-nocookie.com', port=443): Max retries exceeded with url: / (Caused by SSLError(SSLCertVerificationError(1, "[SSL: CERTIFICATE_VERIFY_FAILED] certificate verify failed: Hostname mismatch, certificate is not valid for 'youtube-nocookie.com'. (_ssl.c:1000)")))
None
2024-11-25 19:17:36 - ERROR - [domains_check_MT.py:88] - SSL check error for un.org: [SSL: CERTIFICATE_VERIFY_FAILED] certificate verify failed: self-signed certificate in certificate chain (_ssl.c:1000)
None
2024-11-25 19:17:36 - ERROR - [domains_check_MT.py:88] - SSL check error for washingtonpost.com: [SSL: CERTIFICATE_VERIFY_FAILED] certificate verify failed: unable to get local issuer certificate (_ssl.c:1000)
None
2024-11-25 19:17:37 - ERROR - [domains_check_MT.py:51] - HTTP Request error for washingtonpost.com: HTTPSConnectionPool(host='www.washingtonpost.com', port=443): Read timed out. (read timeout=1)
None
2024-11-25 19:17:40 - ERROR - [domains_check_MT.py:88] - SSL check error for amazonaws.com: [WinError 10061] No connection could be made because the target machine actively refused it
None
2024-11-25 19:17:51 - ERROR - [domains_check_MT.py:88] - SSL check error for macromedia.com: [WinError 10060] A connection attempt failed because the connected party did not properly respond after a period of time, or established connection failed because connected host has failed to respond
None
2024-11-25 19:17:52 - ERROR - [domains_check_MT.py:51] - HTTP Request error for macromedia.com: HTTPConnectionPool(host='macromedia.com', port=80): Max retries exceeded with url: / (Caused by ConnectTimeoutError(<urllib3.connection.HTTPConnection object at 0x00000178DFD9AC90>, 'Connection to macromedia.com timed out. (connect timeout=1)'))
None
2024-11-25 21:07:42 - ERROR - [DataManagement.py:17] - Error occurred while loading domains for user raziel: Expecting value: line 81 column 5 (char 2580)
(<class 'json.decoder.JSONDecodeError'>, JSONDecodeError('Expecting value: line 81 column 5 (char 2580)'), <traceback object at 0x00000213B829BB40>)
Traceback (most recent call last):
  File "C:\Users\razie\DevOps\DomainMonitoringProject\domain-monitoring-project\DataManagement.py", line 10, in load_domains
    data = json.load(f)
           ^^^^^^^^^^^^
  File "C:\Users\razie\AppData\Local\Programs\Python\Python312\Lib\json\__init__.py", line 293, in load
    return loads(fp.read(),
           ^^^^^^^^^^^^^^^^
  File "C:\Users\razie\AppData\Local\Programs\Python\Python312\Lib\json\__init__.py", line 346, in loads
    return _default_decoder.decode(s)
           ^^^^^^^^^^^^^^^^^^^^^^^^^^
  File "C:\Users\razie\AppData\Local\Programs\Python\Python312\Lib\json\decoder.py", line 337, in decode
    obj, end = self.raw_decode(s, idx=_w(s, 0).end())
               ^^^^^^^^^^^^^^^^^^^^^^^^^^^^^^^^^^^^^^
  File "C:\Users\razie\AppData\Local\Programs\Python\Python312\Lib\json\decoder.py", line 355, in raw_decode
    raise JSONDecodeError("Expecting value", s, err.value) from None
json.decoder.JSONDecodeError: Expecting value: line 81 column 5 (char 2580)
2024-11-25 21:08:15 - ERROR - [DataManagement.py:17] - Error occurred while loading domains for user raziel: Expecting value: line 81 column 5 (char 2580)
(<class 'json.decoder.JSONDecodeError'>, JSONDecodeError('Expecting value: line 81 column 5 (char 2580)'), <traceback object at 0x00000213B82AAA80>)
Traceback (most recent call last):
  File "C:\Users\razie\DevOps\DomainMonitoringProject\domain-monitoring-project\DataManagement.py", line 10, in load_domains
    data = json.load(f)
           ^^^^^^^^^^^^
  File "C:\Users\razie\AppData\Local\Programs\Python\Python312\Lib\json\__init__.py", line 293, in load
    return loads(fp.read(),
           ^^^^^^^^^^^^^^^^
  File "C:\Users\razie\AppData\Local\Programs\Python\Python312\Lib\json\__init__.py", line 346, in loads
    return _default_decoder.decode(s)
           ^^^^^^^^^^^^^^^^^^^^^^^^^^
  File "C:\Users\razie\AppData\Local\Programs\Python\Python312\Lib\json\decoder.py", line 337, in decode
    obj, end = self.raw_decode(s, idx=_w(s, 0).end())
               ^^^^^^^^^^^^^^^^^^^^^^^^^^^^^^^^^^^^^^
  File "C:\Users\razie\AppData\Local\Programs\Python\Python312\Lib\json\decoder.py", line 355, in raw_decode
    raise JSONDecodeError("Expecting value", s, err.value) from None
json.decoder.JSONDecodeError: Expecting value: line 81 column 5 (char 2580)
2024-11-25 21:11:19 - ERROR - [DataManagement.py:17] - Error occurred while loading domains for user raziel: Expecting value: line 81 column 5 (char 2580)
(<class 'json.decoder.JSONDecodeError'>, JSONDecodeError('Expecting value: line 81 column 5 (char 2580)'), <traceback object at 0x000002997CAF0840>)
Traceback (most recent call last):
  File "C:\Users\razie\DevOps\DomainMonitoringProject\domain-monitoring-project\DataManagement.py", line 10, in load_domains
    data = json.load(f)
           ^^^^^^^^^^^^
  File "C:\Users\razie\AppData\Local\Programs\Python\Python312\Lib\json\__init__.py", line 293, in load
    return loads(fp.read(),
           ^^^^^^^^^^^^^^^^
  File "C:\Users\razie\AppData\Local\Programs\Python\Python312\Lib\json\__init__.py", line 346, in loads
    return _default_decoder.decode(s)
           ^^^^^^^^^^^^^^^^^^^^^^^^^^
  File "C:\Users\razie\AppData\Local\Programs\Python\Python312\Lib\json\decoder.py", line 337, in decode
    obj, end = self.raw_decode(s, idx=_w(s, 0).end())
               ^^^^^^^^^^^^^^^^^^^^^^^^^^^^^^^^^^^^^^
  File "C:\Users\razie\AppData\Local\Programs\Python\Python312\Lib\json\decoder.py", line 355, in raw_decode
    raise JSONDecodeError("Expecting value", s, err.value) from None
json.decoder.JSONDecodeError: Expecting value: line 81 column 5 (char 2580)
2024-11-25 21:14:44 - ERROR - [app.py:228] - An error occurred while reading domains data for user raziel: Expecting value: line 81 column 5 (char 2580)
(<class 'json.decoder.JSONDecodeError'>, JSONDecodeError('Expecting value: line 81 column 5 (char 2580)'), <traceback object at 0x00000256B1E8B700>)
Traceback (most recent call last):
  File "C:\Users\razie\DevOps\DomainMonitoringProject\domain-monitoring-project\app.py", line 223, in get_domains
    data = json.load(f)
           ^^^^^^^^^^^^
  File "C:\Users\razie\AppData\Local\Programs\Python\Python312\Lib\json\__init__.py", line 293, in load
    return loads(fp.read(),
           ^^^^^^^^^^^^^^^^
  File "C:\Users\razie\AppData\Local\Programs\Python\Python312\Lib\json\__init__.py", line 346, in loads
    return _default_decoder.decode(s)
           ^^^^^^^^^^^^^^^^^^^^^^^^^^
  File "C:\Users\razie\AppData\Local\Programs\Python\Python312\Lib\json\decoder.py", line 337, in decode
    obj, end = self.raw_decode(s, idx=_w(s, 0).end())
               ^^^^^^^^^^^^^^^^^^^^^^^^^^^^^^^^^^^^^^
  File "C:\Users\razie\AppData\Local\Programs\Python\Python312\Lib\json\decoder.py", line 355, in raw_decode
    raise JSONDecodeError("Expecting value", s, err.value) from None
json.decoder.JSONDecodeError: Expecting value: line 81 column 5 (char 2580)
2024-11-25 21:14:54 - ERROR - [app.py:228] - An error occurred while reading domains data for user raziel: Expecting value: line 81 column 5 (char 2580)
(<class 'json.decoder.JSONDecodeError'>, JSONDecodeError('Expecting value: line 81 column 5 (char 2580)'), <traceback object at 0x00000256B1EA8340>)
Traceback (most recent call last):
  File "C:\Users\razie\DevOps\DomainMonitoringProject\domain-monitoring-project\app.py", line 223, in get_domains
    data = json.load(f)
           ^^^^^^^^^^^^
  File "C:\Users\razie\AppData\Local\Programs\Python\Python312\Lib\json\__init__.py", line 293, in load
    return loads(fp.read(),
           ^^^^^^^^^^^^^^^^
  File "C:\Users\razie\AppData\Local\Programs\Python\Python312\Lib\json\__init__.py", line 346, in loads
    return _default_decoder.decode(s)
           ^^^^^^^^^^^^^^^^^^^^^^^^^^
  File "C:\Users\razie\AppData\Local\Programs\Python\Python312\Lib\json\decoder.py", line 337, in decode
    obj, end = self.raw_decode(s, idx=_w(s, 0).end())
               ^^^^^^^^^^^^^^^^^^^^^^^^^^^^^^^^^^^^^^
  File "C:\Users\razie\AppData\Local\Programs\Python\Python312\Lib\json\decoder.py", line 355, in raw_decode
    raise JSONDecodeError("Expecting value", s, err.value) from None
json.decoder.JSONDecodeError: Expecting value: line 81 column 5 (char 2580)
2024-11-25 21:20:03 - ERROR - [domains_check_MT.py:39] - Request error for whatsapp.com: HTTPSConnectionPool(host='www.whatsapp.com', port=443): Read timed out. (read timeout=1)
None
2024-11-25 21:20:04 - ERROR - [domains_check_MT.py:39] - Request error for nih.gov: ('Connection aborted.', RemoteDisconnected('Remote end closed connection without response'))
None
2024-11-25 21:20:04 - ERROR - [domains_check_MT.py:71] - SSL check error for miit.gov.cn: [Errno 11001] getaddrinfo failed
None
2024-11-25 21:20:04 - ERROR - [domains_check_MT.py:39] - Request error for miit.gov.cn: HTTPConnectionPool(host='miit.gov.cn', port=80): Max retries exceeded with url: / (Caused by NameResolutionError("<urllib3.connection.HTTPConnection object at 0x0000017B34BB5250>: Failed to resolve 'miit.gov.cn' ([Errno 11001] getaddrinfo failed)"))
None
2024-11-25 21:20:06 - ERROR - [domains_check_MT.py:71] - SSL check error for wixsite.com: [Errno 11001] getaddrinfo failed
None
2024-11-25 21:20:06 - ERROR - [domains_check_MT.py:39] - Request error for wixsite.com: HTTPConnectionPool(host='wixsite.com', port=80): Max retries exceeded with url: / (Caused by NameResolutionError("<urllib3.connection.HTTPConnection object at 0x0000017B34C224B0>: Failed to resolve 'wixsite.com' ([Errno 11001] getaddrinfo failed)"))
None
2024-11-25 21:20:06 - ERROR - [domains_check_MT.py:39] - Request error for forbes.com: HTTPSConnectionPool(host='www.forbes.com', port=443): Read timed out. (read timeout=1)
None
2024-11-25 21:20:06 - ERROR - [domains_check_MT.py:71] - SSL check error for vk.com: [SSL: CERTIFICATE_VERIFY_FAILED] certificate verify failed: self-signed certificate in certificate chain (_ssl.c:1000)
None
2024-11-25 21:20:07 - ERROR - [domains_check_MT.py:71] - SSL check error for youtube-nocookie.com: [SSL: CERTIFICATE_VERIFY_FAILED] certificate verify failed: Hostname mismatch, certificate is not valid for 'youtube-nocookie.com'. (_ssl.c:1000)
None
2024-11-25 21:20:07 - ERROR - [domains_check_MT.py:71] - SSL check error for washingtonpost.com: [SSL: CERTIFICATE_VERIFY_FAILED] certificate verify failed: unable to get local issuer certificate (_ssl.c:1000)
None
2024-11-25 21:20:07 - ERROR - [domains_check_MT.py:39] - Request error for youtube-nocookie.com: HTTPSConnectionPool(host='youtube-nocookie.com', port=443): Max retries exceeded with url: / (Caused by SSLError(SSLCertVerificationError(1, "[SSL: CERTIFICATE_VERIFY_FAILED] certificate verify failed: Hostname mismatch, certificate is not valid for 'youtube-nocookie.com'. (_ssl.c:1000)")))
None
2024-11-25 21:20:07 - ERROR - [domains_check_MT.py:71] - SSL check error for un.org: [SSL: CERTIFICATE_VERIFY_FAILED] certificate verify failed: self-signed certificate in certificate chain (_ssl.c:1000)
None
2024-11-25 21:20:09 - ERROR - [domains_check_MT.py:39] - Request error for washingtonpost.com: HTTPSConnectionPool(host='www.washingtonpost.com', port=443): Read timed out. (read timeout=1)
None
2024-11-25 21:20:11 - ERROR - [domains_check_MT.py:71] - SSL check error for amazonaws.com: [WinError 10061] No connection could be made because the target machine actively refused it
None
2024-11-25 21:20:23 - ERROR - [domains_check_MT.py:71] - SSL check error for macromedia.com: [WinError 10060] A connection attempt failed because the connected party did not properly respond after a period of time, or established connection failed because connected host has failed to respond
None
2024-11-25 21:20:25 - ERROR - [domains_check_MT.py:39] - Request error for macromedia.com: HTTPConnectionPool(host='macromedia.com', port=80): Max retries exceeded with url: / (Caused by ConnectTimeoutError(<urllib3.connection.HTTPConnection object at 0x0000017B34532150>, 'Connection to macromedia.com timed out. (connect timeout=1)'))
None
2024-11-25 22:13:03 - ERROR - [domains_check_MT.py:78] - SSL check error for {'url': 'www.google.com'}: 'dict' object has no attribute 'replace'
None
2024-11-25 22:13:03 - ERROR - [domains_check_MT.py:78] - SSL check error for {'url': 'www.facebook.com'}: 'dict' object has no attribute 'replace'
None
2024-11-25 22:13:03 - ERROR - [domains_check_MT.py:78] - SSL check error for {'url': 'www.youtube.com'}: 'dict' object has no attribute 'replace'
None
2024-11-25 22:13:03 - ERROR - [domains_check_MT.py:43] - Request error for {'url': 'www.google.com'}: Failed to parse: http://{'url': 'www.google.com'}
None
2024-11-25 22:13:03 - ERROR - [domains_check_MT.py:43] - Request error for {'url': 'www.facebook.com'}: Failed to parse: http://{'url': 'www.facebook.com'}
None
2024-11-25 22:13:03 - ERROR - [domains_check_MT.py:43] - Request error for {'url': 'www.youtube.com'}: Failed to parse: http://{'url': 'www.youtube.com'}
None
2024-11-25 22:16:09 - ERROR - [domains_check_MT.py:43] - Request error for adobe.com: HTTPSConnectionPool(host='www.adobe.com', port=443): Read timed out. (read timeout=1)
None
2024-11-25 22:16:10 - ERROR - [domains_check_MT.py:68] - SSL Error with miit.gov.cn: [Errno 11001] getaddrinfo failed
(<class 'socket.gaierror'>, gaierror(11001, 'getaddrinfo failed'), <traceback object at 0x000001CC5570D840>)
Traceback (most recent call last):
  File "C:\Users\razie\DevOps\DomainMonitoringProject\domain-monitoring-project\domains_check_MT.py", line 58, in check_certificate
    with socket.create_connection((hostname, 443)) as sock:
         ^^^^^^^^^^^^^^^^^^^^^^^^^^^^^^^^^^^^^^^^^
  File "C:\Users\razie\AppData\Local\Programs\Python\Python312\Lib\socket.py", line 841, in create_connection
    for res in getaddrinfo(host, port, 0, SOCK_STREAM):
               ^^^^^^^^^^^^^^^^^^^^^^^^^^^^^^^^^^^^^^^
  File "C:\Users\razie\AppData\Local\Programs\Python\Python312\Lib\socket.py", line 976, in getaddrinfo
    for res in _socket.getaddrinfo(host, port, family, type, proto, flags):
               ^^^^^^^^^^^^^^^^^^^^^^^^^^^^^^^^^^^^^^^^^^^^^^^^^^^^^^^^^^^
socket.gaierror: [Errno 11001] getaddrinfo failed
2024-11-25 22:16:10 - ERROR - [domains_check_MT.py:43] - Request error for miit.gov.cn: HTTPConnectionPool(host='miit.gov.cn', port=80): Max retries exceeded with url: / (Caused by NameResolutionError("<urllib3.connection.HTTPConnection object at 0x000001CC5575D1F0>: Failed to resolve 'miit.gov.cn' ([Errno 11001] getaddrinfo failed)"))
None
2024-11-25 22:16:11 - ERROR - [domains_check_MT.py:43] - Request error for nih.gov: ('Connection aborted.', RemoteDisconnected('Remote end closed connection without response'))
None
2024-11-25 22:16:12 - ERROR - [domains_check_MT.py:43] - Request error for forbes.com: HTTPSConnectionPool(host='www.forbes.com', port=443): Read timed out. (read timeout=1)
None
2024-11-25 22:16:13 - ERROR - [domains_check_MT.py:43] - Request error for nginx.com: HTTPSConnectionPool(host='www.nginx.com', port=443): Read timed out. (read timeout=1)
None
2024-11-25 22:16:13 - ERROR - [domains_check_MT.py:68] - SSL Error with wixsite.com: [Errno 11001] getaddrinfo failed
(<class 'socket.gaierror'>, gaierror(11001, 'getaddrinfo failed'), <traceback object at 0x000001CC5577E440>)
Traceback (most recent call last):
  File "C:\Users\razie\DevOps\DomainMonitoringProject\domain-monitoring-project\domains_check_MT.py", line 58, in check_certificate
    with socket.create_connection((hostname, 443)) as sock:
         ^^^^^^^^^^^^^^^^^^^^^^^^^^^^^^^^^^^^^^^^^
  File "C:\Users\razie\AppData\Local\Programs\Python\Python312\Lib\socket.py", line 841, in create_connection
    for res in getaddrinfo(host, port, 0, SOCK_STREAM):
               ^^^^^^^^^^^^^^^^^^^^^^^^^^^^^^^^^^^^^^^
  File "C:\Users\razie\AppData\Local\Programs\Python\Python312\Lib\socket.py", line 976, in getaddrinfo
    for res in _socket.getaddrinfo(host, port, family, type, proto, flags):
               ^^^^^^^^^^^^^^^^^^^^^^^^^^^^^^^^^^^^^^^^^^^^^^^^^^^^^^^^^^^
socket.gaierror: [Errno 11001] getaddrinfo failed
2024-11-25 22:16:13 - ERROR - [domains_check_MT.py:43] - Request error for wixsite.com: HTTPConnectionPool(host='wixsite.com', port=80): Max retries exceeded with url: / (Caused by NameResolutionError("<urllib3.connection.HTTPConnection object at 0x000001CC55B71760>: Failed to resolve 'wixsite.com' ([Errno 11001] getaddrinfo failed)"))
None
2024-11-25 22:16:13 - ERROR - [domains_check_MT.py:43] - Request error for baidu.com: ('Connection aborted.', RemoteDisconnected('Remote end closed connection without response'))
None
2024-11-25 22:16:13 - ERROR - [domains_check_MT.py:68] - SSL Error with vk.com: [SSL: CERTIFICATE_VERIFY_FAILED] certificate verify failed: self-signed certificate in certificate chain (_ssl.c:1000)
(<class 'ssl.SSLCertVerificationError'>, SSLCertVerificationError(1, '[SSL: CERTIFICATE_VERIFY_FAILED] certificate verify failed: self-signed certificate in certificate chain (_ssl.c:1000)'), <traceback object at 0x000001CC55B6E700>)
Traceback (most recent call last):
  File "C:\Users\razie\DevOps\DomainMonitoringProject\domain-monitoring-project\domains_check_MT.py", line 59, in check_certificate
    with context.wrap_socket(sock, server_hostname=hostname) as ssock:
         ^^^^^^^^^^^^^^^^^^^^^^^^^^^^^^^^^^^^^^^^^^^^^^^^^^^
  File "C:\Users\razie\AppData\Local\Programs\Python\Python312\Lib\ssl.py", line 455, in wrap_socket
    return self.sslsocket_class._create(
           ^^^^^^^^^^^^^^^^^^^^^^^^^^^^^
  File "C:\Users\razie\AppData\Local\Programs\Python\Python312\Lib\ssl.py", line 1041, in _create
    self.do_handshake()
  File "C:\Users\razie\AppData\Local\Programs\Python\Python312\Lib\ssl.py", line 1319, in do_handshake
    self._sslobj.do_handshake()
ssl.SSLCertVerificationError: [SSL: CERTIFICATE_VERIFY_FAILED] certificate verify failed: self-signed certificate in certificate chain (_ssl.c:1000)
2024-11-25 22:16:13 - ERROR - [domains_check_MT.py:68] - SSL Error with youtube-nocookie.com: [SSL: CERTIFICATE_VERIFY_FAILED] certificate verify failed: Hostname mismatch, certificate is not valid for 'youtube-nocookie.com'. (_ssl.c:1000)
(<class 'ssl.SSLCertVerificationError'>, SSLCertVerificationError(1, "[SSL: CERTIFICATE_VERIFY_FAILED] certificate verify failed: Hostname mismatch, certificate is not valid for 'youtube-nocookie.com'. (_ssl.c:1000)"), <traceback object at 0x000001CC55B5E400>)
Traceback (most recent call last):
  File "C:\Users\razie\DevOps\DomainMonitoringProject\domain-monitoring-project\domains_check_MT.py", line 59, in check_certificate
    with context.wrap_socket(sock, server_hostname=hostname) as ssock:
         ^^^^^^^^^^^^^^^^^^^^^^^^^^^^^^^^^^^^^^^^^^^^^^^^^^^
  File "C:\Users\razie\AppData\Local\Programs\Python\Python312\Lib\ssl.py", line 455, in wrap_socket
    return self.sslsocket_class._create(
           ^^^^^^^^^^^^^^^^^^^^^^^^^^^^^
  File "C:\Users\razie\AppData\Local\Programs\Python\Python312\Lib\ssl.py", line 1041, in _create
    self.do_handshake()
  File "C:\Users\razie\AppData\Local\Programs\Python\Python312\Lib\ssl.py", line 1319, in do_handshake
    self._sslobj.do_handshake()
ssl.SSLCertVerificationError: [SSL: CERTIFICATE_VERIFY_FAILED] certificate verify failed: Hostname mismatch, certificate is not valid for 'youtube-nocookie.com'. (_ssl.c:1000)
2024-11-25 22:16:14 - ERROR - [domains_check_MT.py:43] - Request error for youtube-nocookie.com: HTTPSConnectionPool(host='youtube-nocookie.com', port=443): Max retries exceeded with url: / (Caused by SSLError(SSLCertVerificationError(1, "[SSL: CERTIFICATE_VERIFY_FAILED] certificate verify failed: Hostname mismatch, certificate is not valid for 'youtube-nocookie.com'. (_ssl.c:1000)")))
None
2024-11-25 22:16:14 - ERROR - [domains_check_MT.py:68] - SSL Error with un.org: [SSL: CERTIFICATE_VERIFY_FAILED] certificate verify failed: self-signed certificate in certificate chain (_ssl.c:1000)
(<class 'ssl.SSLCertVerificationError'>, SSLCertVerificationError(1, '[SSL: CERTIFICATE_VERIFY_FAILED] certificate verify failed: self-signed certificate in certificate chain (_ssl.c:1000)'), <traceback object at 0x000001CC55AB8380>)
Traceback (most recent call last):
  File "C:\Users\razie\DevOps\DomainMonitoringProject\domain-monitoring-project\domains_check_MT.py", line 59, in check_certificate
    with context.wrap_socket(sock, server_hostname=hostname) as ssock:
         ^^^^^^^^^^^^^^^^^^^^^^^^^^^^^^^^^^^^^^^^^^^^^^^^^^^
  File "C:\Users\razie\AppData\Local\Programs\Python\Python312\Lib\ssl.py", line 455, in wrap_socket
    return self.sslsocket_class._create(
           ^^^^^^^^^^^^^^^^^^^^^^^^^^^^^
  File "C:\Users\razie\AppData\Local\Programs\Python\Python312\Lib\ssl.py", line 1041, in _create
    self.do_handshake()
  File "C:\Users\razie\AppData\Local\Programs\Python\Python312\Lib\ssl.py", line 1319, in do_handshake
    self._sslobj.do_handshake()
ssl.SSLCertVerificationError: [SSL: CERTIFICATE_VERIFY_FAILED] certificate verify failed: self-signed certificate in certificate chain (_ssl.c:1000)
2024-11-25 22:16:14 - ERROR - [domains_check_MT.py:43] - Request error for f5.com: HTTPSConnectionPool(host='www.f5.com', port=443): Read timed out. (read timeout=1)
None
2024-11-25 22:16:15 - ERROR - [domains_check_MT.py:43] - Request error for washingtonpost.com: HTTPSConnectionPool(host='www.washingtonpost.com', port=443): Read timed out. (read timeout=1)
None
2024-11-25 22:16:18 - ERROR - [domains_check_MT.py:68] - SSL Error with amazonaws.com: [WinError 10061] No connection could be made because the target machine actively refused it
(<class 'ConnectionRefusedError'>, ConnectionRefusedError(10061, 'No connection could be made because the target machine actively refused it', None, 10061, None), <traceback object at 0x000001CC556DDDC0>)
Traceback (most recent call last):
  File "C:\Users\razie\DevOps\DomainMonitoringProject\domain-monitoring-project\domains_check_MT.py", line 58, in check_certificate
    with socket.create_connection((hostname, 443)) as sock:
         ^^^^^^^^^^^^^^^^^^^^^^^^^^^^^^^^^^^^^^^^^
  File "C:\Users\razie\AppData\Local\Programs\Python\Python312\Lib\socket.py", line 865, in create_connection
    raise exceptions[0]
  File "C:\Users\razie\AppData\Local\Programs\Python\Python312\Lib\socket.py", line 850, in create_connection
    sock.connect(sa)
ConnectionRefusedError: [WinError 10061] No connection could be made because the target machine actively refused it
2024-11-25 22:16:30 - ERROR - [domains_check_MT.py:68] - SSL Error with macromedia.com: [WinError 10060] A connection attempt failed because the connected party did not properly respond after a period of time, or established connection failed because connected host has failed to respond
(<class 'TimeoutError'>, TimeoutError(10060, 'A connection attempt failed because the connected party did not properly respond after a period of time, or established connection failed because connected host has failed to respond', None, 10060, None), <traceback object at 0x000001CC5423B3C0>)
Traceback (most recent call last):
  File "C:\Users\razie\DevOps\DomainMonitoringProject\domain-monitoring-project\domains_check_MT.py", line 58, in check_certificate
    with socket.create_connection((hostname, 443)) as sock:
         ^^^^^^^^^^^^^^^^^^^^^^^^^^^^^^^^^^^^^^^^^
  File "C:\Users\razie\AppData\Local\Programs\Python\Python312\Lib\socket.py", line 865, in create_connection
    raise exceptions[0]
  File "C:\Users\razie\AppData\Local\Programs\Python\Python312\Lib\socket.py", line 850, in create_connection
    sock.connect(sa)
TimeoutError: [WinError 10060] A connection attempt failed because the connected party did not properly respond after a period of time, or established connection failed because connected host has failed to respond
2024-11-25 22:16:31 - ERROR - [domains_check_MT.py:43] - Request error for macromedia.com: HTTPConnectionPool(host='macromedia.com', port=80): Max retries exceeded with url: / (Caused by ConnectTimeoutError(<urllib3.connection.HTTPConnection object at 0x000001CC55B70950>, 'Connection to macromedia.com timed out. (connect timeout=1)'))
None
2024-11-25 22:16:56 - ERROR - [domains_check_MT.py:68] - SSL Error with wordpress.co.il: [SSL: CERTIFICATE_VERIFY_FAILED] certificate verify failed: self-signed certificate (_ssl.c:1000)
(<class 'ssl.SSLCertVerificationError'>, SSLCertVerificationError(1, '[SSL: CERTIFICATE_VERIFY_FAILED] certificate verify failed: self-signed certificate (_ssl.c:1000)'), <traceback object at 0x000001CC541B2340>)
Traceback (most recent call last):
  File "C:\Users\razie\DevOps\DomainMonitoringProject\domain-monitoring-project\domains_check_MT.py", line 59, in check_certificate
    with context.wrap_socket(sock, server_hostname=hostname) as ssock:
         ^^^^^^^^^^^^^^^^^^^^^^^^^^^^^^^^^^^^^^^^^^^^^^^^^^^
  File "C:\Users\razie\AppData\Local\Programs\Python\Python312\Lib\ssl.py", line 455, in wrap_socket
    return self.sslsocket_class._create(
           ^^^^^^^^^^^^^^^^^^^^^^^^^^^^^
  File "C:\Users\razie\AppData\Local\Programs\Python\Python312\Lib\ssl.py", line 1041, in _create
    self.do_handshake()
  File "C:\Users\razie\AppData\Local\Programs\Python\Python312\Lib\ssl.py", line 1319, in do_handshake
    self._sslobj.do_handshake()
ssl.SSLCertVerificationError: [SSL: CERTIFICATE_VERIFY_FAILED] certificate verify failed: self-signed certificate (_ssl.c:1000)
2024-11-25 22:21:37 - ERROR - [domains_check_MT.py:68] - SSL Error with weibo.co.il: [Errno 11001] getaddrinfo failed
(<class 'socket.gaierror'>, gaierror(11001, 'getaddrinfo failed'), <traceback object at 0x00000154B5C308C0>)
Traceback (most recent call last):
  File "C:\Users\razie\DevOps\DomainMonitoringProject\domain-monitoring-project\domains_check_MT.py", line 58, in check_certificate
    with socket.create_connection((hostname, 443)) as sock:
         ^^^^^^^^^^^^^^^^^^^^^^^^^^^^^^^^^^^^^^^^^
  File "C:\Users\razie\AppData\Local\Programs\Python\Python312\Lib\socket.py", line 841, in create_connection
    for res in getaddrinfo(host, port, 0, SOCK_STREAM):
               ^^^^^^^^^^^^^^^^^^^^^^^^^^^^^^^^^^^^^^^
  File "C:\Users\razie\AppData\Local\Programs\Python\Python312\Lib\socket.py", line 976, in getaddrinfo
    for res in _socket.getaddrinfo(host, port, family, type, proto, flags):
               ^^^^^^^^^^^^^^^^^^^^^^^^^^^^^^^^^^^^^^^^^^^^^^^^^^^^^^^^^^^
socket.gaierror: [Errno 11001] getaddrinfo failed
2024-11-25 22:21:37 - ERROR - [domains_check_MT.py:43] - Request error for weibo.co.il: HTTPConnectionPool(host='weibo.co.il', port=80): Max retries exceeded with url: / (Caused by NameResolutionError("<urllib3.connection.HTTPConnection object at 0x00000154B5C395B0>: Failed to resolve 'weibo.co.il' ([Errno 11001] getaddrinfo failed)"))
None
2024-11-25 22:23:30 - ERROR - [domains_check_MT.py:43] - Request error for google.com: HTTPConnectionPool(host='www.google.com', port=80): Read timed out. (read timeout=1)
None
2024-11-25 22:23:41 - ERROR - [domains_check_MT.py:43] - Request error for google.com: HTTPConnectionPool(host='www.google.com', port=80): Read timed out. (read timeout=1)
None
2024-11-25 22:28:18 - ERROR - [domains_check_MT.py:68] - SSL Error with google.con: [Errno 11001] getaddrinfo failed
(<class 'socket.gaierror'>, gaierror(11001, 'getaddrinfo failed'), <traceback object at 0x000001CC6D615380>)
Traceback (most recent call last):
  File "C:\Users\razie\DevOps\DomainMonitoringProject\domain-monitoring-project\domains_check_MT.py", line 58, in check_certificate
    with socket.create_connection((hostname, 443)) as sock:
         ^^^^^^^^^^^^^^^^^^^^^^^^^^^^^^^^^^^^^^^^^
  File "C:\Users\razie\AppData\Local\Programs\Python\Python312\Lib\socket.py", line 841, in create_connection
    for res in getaddrinfo(host, port, 0, SOCK_STREAM):
               ^^^^^^^^^^^^^^^^^^^^^^^^^^^^^^^^^^^^^^^
  File "C:\Users\razie\AppData\Local\Programs\Python\Python312\Lib\socket.py", line 976, in getaddrinfo
    for res in _socket.getaddrinfo(host, port, family, type, proto, flags):
               ^^^^^^^^^^^^^^^^^^^^^^^^^^^^^^^^^^^^^^^^^^^^^^^^^^^^^^^^^^^
socket.gaierror: [Errno 11001] getaddrinfo failed
2024-11-25 22:28:18 - ERROR - [domains_check_MT.py:43] - Request error for google.con: HTTPConnectionPool(host='google.con', port=80): Max retries exceeded with url: / (Caused by NameResolutionError("<urllib3.connection.HTTPConnection object at 0x000001CC6D183A40>: Failed to resolve 'google.con' ([Errno 11001] getaddrinfo failed)"))
None
2024-11-25 22:53:23 - ERROR - [DataManagement.py:62] - Error updating domains for raziel: 'dict' object has no attribute 'append'
(<class 'AttributeError'>, AttributeError("'dict' object has no attribute 'append'"), <traceback object at 0x000001CCFA9527C0>)
Traceback (most recent call last):
  File "C:\Users\razie\DevOps\DomainMonitoringProject\domain-monitoring-project\DataManagement.py", line 54, in update_domains
    current_domains.append(new_domain)
    ^^^^^^^^^^^^^^^^^^^^^^
AttributeError: 'dict' object has no attribute 'append'
2024-11-25 23:02:44 - ERROR - [DataManagement.py:78] - Error updating domains for user raziel: 'url_to_replace'
(<class 'KeyError'>, KeyError('url_to_replace'), <traceback object at 0x0000020A7486B840>)
Traceback (most recent call last):
  File "C:\Users\razie\DevOps\DomainMonitoringProject\domain-monitoring-project\DataManagement.py", line 49, in update_domains
    if current_domain['url'] == new_domain['url_to_replace']:
                                ~~~~~~~~~~^^^^^^^^^^^^^^^^^^
KeyError: 'url_to_replace'
2024-11-25 23:03:15 - ERROR - [DataManagement.py:78] - Error updating domains for user raziel: 'url_to_replace'
(<class 'KeyError'>, KeyError('url_to_replace'), <traceback object at 0x0000020A77D54700>)
Traceback (most recent call last):
  File "C:\Users\razie\DevOps\DomainMonitoringProject\domain-monitoring-project\DataManagement.py", line 49, in update_domains
    if current_domain['url'] == new_domain['url_to_replace']:
                                ~~~~~~~~~~^^^^^^^^^^^^^^^^^^
KeyError: 'url_to_replace'
2024-11-25 23:35:00 - ERROR - [DataManagement.py:72] - Error updating domains for user raziel: Missing 'old_url' for domain replacement.
(<class 'ValueError'>, ValueError("Missing 'old_url' for domain replacement."), <traceback object at 0x0000021F54C70A80>)
Traceback (most recent call last):
  File "C:\Users\razie\DevOps\DomainMonitoringProject\domain-monitoring-project\DataManagement.py", line 47, in update_domains
    raise ValueError("Missing 'old_url' for domain replacement.")
ValueError: Missing 'old_url' for domain replacement.
