2024-11-26 00:12:07 - ERROR - [app.py:222] - Error checking domains: 'str' object has no attribute 'get'
(<class 'AttributeError'>, AttributeError("'str' object has no attribute 'get'"), <traceback object at 0x0000020037E858C0>)
Traceback (most recent call last):
  File "C:\Users\razie\DevOps\DomainMonitoringProject\domain-monitoring-project\app.py", line 200, in check_domains
    old_url = domain.get('old_url')  # בדיקת קיומו של 'old_url'
              ^^^^^^^^^^
AttributeError: 'str' object has no attribute 'get'
2024-11-26 00:15:24 - ERROR - [app.py:226] - Error checking domains: check_url_mt() missing 1 required positional argument: 'username'
(<class 'TypeError'>, TypeError("check_url_mt() missing 1 required positional argument: 'username'"), <traceback object at 0x000001F221F06DC0>)
Traceback (most recent call last):
  File "C:\Users\razie\DevOps\DomainMonitoringProject\domain-monitoring-project\app.py", line 221, in check_domains
    results.append(check_url(domain['url']))
                   ^^^^^^^^^^^^^^^^^^^^^^^^
TypeError: check_url_mt() missing 1 required positional argument: 'username'
2024-11-26 00:16:25 - ERROR - [app.py:204] - Error checking domains: name 'check_url_mt' is not defined
(<class 'NameError'>, NameError("name 'check_url_mt' is not defined"), <traceback object at 0x00000233981BE240>)
Traceback (most recent call last):
  File "C:\Users\razie\DevOps\DomainMonitoringProject\domain-monitoring-project\app.py", line 199, in check_domains
    results = check_url_mt(domains, username)
              ^^^^^^^^^^^^
NameError: name 'check_url_mt' is not defined. Did you mean: 'check_url'?
2024-11-26 00:19:05 - ERROR - [DataManagement.py:76] - Error updating domains for user raziel: Missing 'old_url' for domain replacement.
(<class 'ValueError'>, ValueError("Missing 'old_url' for domain replacement."), <traceback object at 0x0000028873DEEF80>)
Traceback (most recent call last):
  File "C:\Users\razie\DevOps\DomainMonitoringProject\domain-monitoring-project\DataManagement.py", line 47, in update_domains
    raise ValueError("Missing 'old_url' for domain replacement.")
ValueError: Missing 'old_url' for domain replacement.
2024-11-26 00:49:28 - ERROR - [app.py:213] - Error checking domains: name 'check_url_mt' is not defined
(<class 'NameError'>, NameError("name 'check_url_mt' is not defined"), <traceback object at 0x00000281D73B7300>)
Traceback (most recent call last):
  File "C:\Users\razie\DevOps\DomainMonitoringProject\domain-monitoring-project\app.py", line 208, in check_domains
    check_url_mt([domain["url"]], username)
    ^^^^^^^^^^^^
NameError: name 'check_url_mt' is not defined. Did you mean: 'check_url'?
2024-11-26 00:50:12 - ERROR - [DataManagement.py:76] - Error updating domains for user raziel: Missing 'old_url' for domain replacement.
(<class 'ValueError'>, ValueError("Missing 'old_url' for domain replacement."), <traceback object at 0x000001CA133878C0>)
Traceback (most recent call last):
  File "C:\Users\razie\DevOps\DomainMonitoringProject\domain-monitoring-project\DataManagement.py", line 47, in update_domains
    raise ValueError("Missing 'old_url' for domain replacement.")
ValueError: Missing 'old_url' for domain replacement.
2024-11-26 00:50:14 - ERROR - [DataManagement.py:76] - Error updating domains for user raziel: Missing 'old_url' for domain replacement.
(<class 'ValueError'>, ValueError("Missing 'old_url' for domain replacement."), <traceback object at 0x000001CA13083840>)
Traceback (most recent call last):
  File "C:\Users\razie\DevOps\DomainMonitoringProject\domain-monitoring-project\DataManagement.py", line 47, in update_domains
    raise ValueError("Missing 'old_url' for domain replacement.")
ValueError: Missing 'old_url' for domain replacement.
2024-11-26 00:50:35 - ERROR - [DataManagement.py:76] - Error updating domains for user raziel: Missing 'old_url' for domain replacement.
(<class 'ValueError'>, ValueError("Missing 'old_url' for domain replacement."), <traceback object at 0x000001CA133A4600>)
Traceback (most recent call last):
  File "C:\Users\razie\DevOps\DomainMonitoringProject\domain-monitoring-project\DataManagement.py", line 47, in update_domains
    raise ValueError("Missing 'old_url' for domain replacement.")
ValueError: Missing 'old_url' for domain replacement.
2024-11-26 00:51:38 - ERROR - [DataManagement.py:76] - Error updating domains for user raziel: Missing 'old_url' for domain replacement.
(<class 'ValueError'>, ValueError("Missing 'old_url' for domain replacement."), <traceback object at 0x0000016BB1E1B2C0>)
Traceback (most recent call last):
  File "C:\Users\razie\DevOps\DomainMonitoringProject\domain-monitoring-project\DataManagement.py", line 47, in update_domains
    raise ValueError("Missing 'old_url' for domain replacement.")
ValueError: Missing 'old_url' for domain replacement.
2024-11-26 00:52:27 - ERROR - [DataManagement.py:76] - Error updating domains for user raziel: Missing 'old_url' for domain replacement.
(<class 'ValueError'>, ValueError("Missing 'old_url' for domain replacement."), <traceback object at 0x0000016BB56A8EC0>)
Traceback (most recent call last):
  File "C:\Users\razie\DevOps\DomainMonitoringProject\domain-monitoring-project\DataManagement.py", line 47, in update_domains
    raise ValueError("Missing 'old_url' for domain replacement.")
ValueError: Missing 'old_url' for domain replacement.
2024-11-26 00:52:39 - ERROR - [DataManagement.py:76] - Error updating domains for user raziel: Missing 'old_url' for domain replacement.
(<class 'ValueError'>, ValueError("Missing 'old_url' for domain replacement."), <traceback object at 0x0000016BB568F780>)
Traceback (most recent call last):
  File "C:\Users\razie\DevOps\DomainMonitoringProject\domain-monitoring-project\DataManagement.py", line 47, in update_domains
    raise ValueError("Missing 'old_url' for domain replacement.")
ValueError: Missing 'old_url' for domain replacement.
2024-11-26 00:52:49 - ERROR - [DataManagement.py:76] - Error updating domains for user raziel: Missing 'old_url' for domain replacement.
(<class 'ValueError'>, ValueError("Missing 'old_url' for domain replacement."), <traceback object at 0x0000016BB56AB800>)
Traceback (most recent call last):
  File "C:\Users\razie\DevOps\DomainMonitoringProject\domain-monitoring-project\DataManagement.py", line 47, in update_domains
    raise ValueError("Missing 'old_url' for domain replacement.")
ValueError: Missing 'old_url' for domain replacement.
2024-11-26 01:06:45 - ERROR - [domains_check_MT.py:43] - Request error for plus.google.com: HTTPSConnectionPool(host='workspaceupdates.googleblog.com', port=443): Read timed out. (read timeout=1)
None
2024-11-26 01:06:46 - ERROR - [domains_check_MT.py:43] - Request error for nih.gov: ('Connection aborted.', RemoteDisconnected('Remote end closed connection without response'))
None
2024-11-26 01:06:46 - ERROR - [domains_check_MT.py:69] - SSL Error with miit.gov.cn: [Errno 11001] getaddrinfo failed
(<class 'socket.gaierror'>, gaierror(11001, 'getaddrinfo failed'), <traceback object at 0x000001963CEA4B80>)
Traceback (most recent call last):
  File "C:\Users\razie\DevOps\DomainMonitoringProject\domain-monitoring-project\domains_check_MT.py", line 59, in check_certificate
    with socket.create_connection((hostname, 443)) as sock:
         ^^^^^^^^^^^^^^^^^^^^^^^^^^^^^^^^^^^^^^^^^
  File "C:\Users\razie\AppData\Local\Programs\Python\Python312\Lib\socket.py", line 841, in create_connection
    for res in getaddrinfo(host, port, 0, SOCK_STREAM):
               ^^^^^^^^^^^^^^^^^^^^^^^^^^^^^^^^^^^^^^^
  File "C:\Users\razie\AppData\Local\Programs\Python\Python312\Lib\socket.py", line 976, in getaddrinfo
    for res in _socket.getaddrinfo(host, port, family, type, proto, flags):
               ^^^^^^^^^^^^^^^^^^^^^^^^^^^^^^^^^^^^^^^^^^^^^^^^^^^^^^^^^^^
socket.gaierror: [Errno 11001] getaddrinfo failed
2024-11-26 01:06:46 - ERROR - [domains_check_MT.py:43] - Request error for miit.gov.cn: HTTPConnectionPool(host='miit.gov.cn', port=80): Max retries exceeded with url: / (Caused by NameResolutionError("<urllib3.connection.HTTPConnection object at 0x000001963CB04980>: Failed to resolve 'miit.gov.cn' ([Errno 11001] getaddrinfo failed)"))
None
2024-11-26 01:06:48 - ERROR - [domains_check_MT.py:43] - Request error for nginx.com: HTTPSConnectionPool(host='www.nginx.com', port=443): Read timed out. (read timeout=1)
None
2024-11-26 01:06:49 - ERROR - [domains_check_MT.py:69] - SSL Error with vk.com: [SSL: CERTIFICATE_VERIFY_FAILED] certificate verify failed: self-signed certificate in certificate chain (_ssl.c:1000)
(<class 'ssl.SSLCertVerificationError'>, SSLCertVerificationError(1, '[SSL: CERTIFICATE_VERIFY_FAILED] certificate verify failed: self-signed certificate in certificate chain (_ssl.c:1000)'), <traceback object at 0x000001963CEDC080>)
Traceback (most recent call last):
  File "C:\Users\razie\DevOps\DomainMonitoringProject\domain-monitoring-project\domains_check_MT.py", line 60, in check_certificate
    with context.wrap_socket(sock, server_hostname=hostname) as ssock:
         ^^^^^^^^^^^^^^^^^^^^^^^^^^^^^^^^^^^^^^^^^^^^^^^^^^^
  File "C:\Users\razie\AppData\Local\Programs\Python\Python312\Lib\ssl.py", line 455, in wrap_socket
    return self.sslsocket_class._create(
           ^^^^^^^^^^^^^^^^^^^^^^^^^^^^^
  File "C:\Users\razie\AppData\Local\Programs\Python\Python312\Lib\ssl.py", line 1041, in _create
    self.do_handshake()
  File "C:\Users\razie\AppData\Local\Programs\Python\Python312\Lib\ssl.py", line 1319, in do_handshake
    self._sslobj.do_handshake()
ssl.SSLCertVerificationError: [SSL: CERTIFICATE_VERIFY_FAILED] certificate verify failed: self-signed certificate in certificate chain (_ssl.c:1000)
2024-11-26 01:06:49 - ERROR - [domains_check_MT.py:69] - SSL Error with wixsite.com: [Errno 11001] getaddrinfo failed
(<class 'socket.gaierror'>, gaierror(11001, 'getaddrinfo failed'), <traceback object at 0x000001963CA3E5C0>)
Traceback (most recent call last):
  File "C:\Users\razie\DevOps\DomainMonitoringProject\domain-monitoring-project\domains_check_MT.py", line 59, in check_certificate
    with socket.create_connection((hostname, 443)) as sock:
         ^^^^^^^^^^^^^^^^^^^^^^^^^^^^^^^^^^^^^^^^^
  File "C:\Users\razie\AppData\Local\Programs\Python\Python312\Lib\socket.py", line 841, in create_connection
    for res in getaddrinfo(host, port, 0, SOCK_STREAM):
               ^^^^^^^^^^^^^^^^^^^^^^^^^^^^^^^^^^^^^^^
  File "C:\Users\razie\AppData\Local\Programs\Python\Python312\Lib\socket.py", line 976, in getaddrinfo
    for res in _socket.getaddrinfo(host, port, family, type, proto, flags):
               ^^^^^^^^^^^^^^^^^^^^^^^^^^^^^^^^^^^^^^^^^^^^^^^^^^^^^^^^^^^
socket.gaierror: [Errno 11001] getaddrinfo failed
2024-11-26 01:06:49 - ERROR - [domains_check_MT.py:43] - Request error for wixsite.com: HTTPConnectionPool(host='wixsite.com', port=80): Max retries exceeded with url: / (Caused by NameResolutionError("<urllib3.connection.HTTPConnection object at 0x000001963CA711F0>: Failed to resolve 'wixsite.com' ([Errno 11001] getaddrinfo failed)"))
None
2024-11-26 01:06:49 - ERROR - [domains_check_MT.py:69] - SSL Error with youtube-nocookie.com: [SSL: CERTIFICATE_VERIFY_FAILED] certificate verify failed: Hostname mismatch, certificate is not valid for 'youtube-nocookie.com'. (_ssl.c:1000)
(<class 'ssl.SSLCertVerificationError'>, SSLCertVerificationError(1, "[SSL: CERTIFICATE_VERIFY_FAILED] certificate verify failed: Hostname mismatch, certificate is not valid for 'youtube-nocookie.com'. (_ssl.c:1000)"), <traceback object at 0x000001963CAE9000>)
Traceback (most recent call last):
  File "C:\Users\razie\DevOps\DomainMonitoringProject\domain-monitoring-project\domains_check_MT.py", line 60, in check_certificate
    with context.wrap_socket(sock, server_hostname=hostname) as ssock:
         ^^^^^^^^^^^^^^^^^^^^^^^^^^^^^^^^^^^^^^^^^^^^^^^^^^^
  File "C:\Users\razie\AppData\Local\Programs\Python\Python312\Lib\ssl.py", line 455, in wrap_socket
    return self.sslsocket_class._create(
           ^^^^^^^^^^^^^^^^^^^^^^^^^^^^^
  File "C:\Users\razie\AppData\Local\Programs\Python\Python312\Lib\ssl.py", line 1041, in _create
    self.do_handshake()
  File "C:\Users\razie\AppData\Local\Programs\Python\Python312\Lib\ssl.py", line 1319, in do_handshake
    self._sslobj.do_handshake()
ssl.SSLCertVerificationError: [SSL: CERTIFICATE_VERIFY_FAILED] certificate verify failed: Hostname mismatch, certificate is not valid for 'youtube-nocookie.com'. (_ssl.c:1000)
2024-11-26 01:06:49 - ERROR - [domains_check_MT.py:43] - Request error for youtube-nocookie.com: HTTPSConnectionPool(host='youtube-nocookie.com', port=443): Max retries exceeded with url: / (Caused by SSLError(SSLCertVerificationError(1, "[SSL: CERTIFICATE_VERIFY_FAILED] certificate verify failed: Hostname mismatch, certificate is not valid for 'youtube-nocookie.com'. (_ssl.c:1000)")))
None
2024-11-26 01:06:49 - ERROR - [domains_check_MT.py:43] - Request error for forbes.com: HTTPSConnectionPool(host='www.forbes.com', port=443): Read timed out. (read timeout=1)
None
2024-11-26 01:06:49 - ERROR - [domains_check_MT.py:43] - Request error for f5.com: HTTPSConnectionPool(host='www.f5.com', port=443): Read timed out. (read timeout=1)
None
2024-11-26 01:06:50 - ERROR - [domains_check_MT.py:69] - SSL Error with washingtonpost.com: [SSL: CERTIFICATE_VERIFY_FAILED] certificate verify failed: unable to get local issuer certificate (_ssl.c:1000)
(<class 'ssl.SSLCertVerificationError'>, SSLCertVerificationError(1, '[SSL: CERTIFICATE_VERIFY_FAILED] certificate verify failed: unable to get local issuer certificate (_ssl.c:1000)'), <traceback object at 0x000001963CA6A140>)
Traceback (most recent call last):
  File "C:\Users\razie\DevOps\DomainMonitoringProject\domain-monitoring-project\domains_check_MT.py", line 60, in check_certificate
    with context.wrap_socket(sock, server_hostname=hostname) as ssock:
         ^^^^^^^^^^^^^^^^^^^^^^^^^^^^^^^^^^^^^^^^^^^^^^^^^^^
  File "C:\Users\razie\AppData\Local\Programs\Python\Python312\Lib\ssl.py", line 455, in wrap_socket
    return self.sslsocket_class._create(
           ^^^^^^^^^^^^^^^^^^^^^^^^^^^^^
  File "C:\Users\razie\AppData\Local\Programs\Python\Python312\Lib\ssl.py", line 1041, in _create
    self.do_handshake()
  File "C:\Users\razie\AppData\Local\Programs\Python\Python312\Lib\ssl.py", line 1319, in do_handshake
    self._sslobj.do_handshake()
ssl.SSLCertVerificationError: [SSL: CERTIFICATE_VERIFY_FAILED] certificate verify failed: unable to get local issuer certificate (_ssl.c:1000)
2024-11-26 01:06:50 - ERROR - [domains_check_MT.py:69] - SSL Error with un.org: [SSL: CERTIFICATE_VERIFY_FAILED] certificate verify failed: self-signed certificate in certificate chain (_ssl.c:1000)
(<class 'ssl.SSLCertVerificationError'>, SSLCertVerificationError(1, '[SSL: CERTIFICATE_VERIFY_FAILED] certificate verify failed: self-signed certificate in certificate chain (_ssl.c:1000)'), <traceback object at 0x000001963B55D280>)
Traceback (most recent call last):
  File "C:\Users\razie\DevOps\DomainMonitoringProject\domain-monitoring-project\domains_check_MT.py", line 60, in check_certificate
    with context.wrap_socket(sock, server_hostname=hostname) as ssock:
         ^^^^^^^^^^^^^^^^^^^^^^^^^^^^^^^^^^^^^^^^^^^^^^^^^^^
  File "C:\Users\razie\AppData\Local\Programs\Python\Python312\Lib\ssl.py", line 455, in wrap_socket
    return self.sslsocket_class._create(
           ^^^^^^^^^^^^^^^^^^^^^^^^^^^^^
  File "C:\Users\razie\AppData\Local\Programs\Python\Python312\Lib\ssl.py", line 1041, in _create
    self.do_handshake()
  File "C:\Users\razie\AppData\Local\Programs\Python\Python312\Lib\ssl.py", line 1319, in do_handshake
    self._sslobj.do_handshake()
ssl.SSLCertVerificationError: [SSL: CERTIFICATE_VERIFY_FAILED] certificate verify failed: self-signed certificate in certificate chain (_ssl.c:1000)
2024-11-26 01:06:51 - ERROR - [domains_check_MT.py:43] - Request error for washingtonpost.com: HTTPSConnectionPool(host='www.washingtonpost.com', port=443): Read timed out. (read timeout=1)
None
2024-11-26 01:06:53 - ERROR - [domains_check_MT.py:69] - SSL Error with amazonaws.com: [WinError 10061] No connection could be made because the target machine actively refused it
(<class 'ConnectionRefusedError'>, ConnectionRefusedError(10061, 'No connection could be made because the target machine actively refused it', None, 10061, None), <traceback object at 0x000001963B54CCC0>)
Traceback (most recent call last):
  File "C:\Users\razie\DevOps\DomainMonitoringProject\domain-monitoring-project\domains_check_MT.py", line 59, in check_certificate
    with socket.create_connection((hostname, 443)) as sock:
         ^^^^^^^^^^^^^^^^^^^^^^^^^^^^^^^^^^^^^^^^^
  File "C:\Users\razie\AppData\Local\Programs\Python\Python312\Lib\socket.py", line 865, in create_connection
    raise exceptions[0]
  File "C:\Users\razie\AppData\Local\Programs\Python\Python312\Lib\socket.py", line 850, in create_connection
    sock.connect(sa)
ConnectionRefusedError: [WinError 10061] No connection could be made because the target machine actively refused it
2024-11-26 01:07:05 - ERROR - [domains_check_MT.py:69] - SSL Error with macromedia.com: [WinError 10060] A connection attempt failed because the connected party did not properly respond after a period of time, or established connection failed because connected host has failed to respond
(<class 'TimeoutError'>, TimeoutError(10060, 'A connection attempt failed because the connected party did not properly respond after a period of time, or established connection failed because connected host has failed to respond', None, 10060, None), <traceback object at 0x000001963CEDC6C0>)
Traceback (most recent call last):
  File "C:\Users\razie\DevOps\DomainMonitoringProject\domain-monitoring-project\domains_check_MT.py", line 59, in check_certificate
    with socket.create_connection((hostname, 443)) as sock:
         ^^^^^^^^^^^^^^^^^^^^^^^^^^^^^^^^^^^^^^^^^
  File "C:\Users\razie\AppData\Local\Programs\Python\Python312\Lib\socket.py", line 865, in create_connection
    raise exceptions[0]
  File "C:\Users\razie\AppData\Local\Programs\Python\Python312\Lib\socket.py", line 850, in create_connection
    sock.connect(sa)
TimeoutError: [WinError 10060] A connection attempt failed because the connected party did not properly respond after a period of time, or established connection failed because connected host has failed to respond
2024-11-26 01:07:07 - ERROR - [domains_check_MT.py:43] - Request error for macromedia.com: HTTPConnectionPool(host='macromedia.com', port=80): Max retries exceeded with url: / (Caused by ConnectTimeoutError(<urllib3.connection.HTTPConnection object at 0x000001963CE6C260>, 'Connection to macromedia.com timed out. (connect timeout=1)'))
None
2024-11-26 14:07:14 - ERROR - [domains_check_MT.py:44] - Request error for adobe.com: HTTPSConnectionPool(host='www.adobe.com', port=443): Read timed out. (read timeout=1)
None
2024-11-26 14:07:15 - ERROR - [domains_check_MT.py:71] - SSL Error with miit.gov.cn: [Errno 11001] getaddrinfo failed
(<class 'socket.gaierror'>, gaierror(11001, 'getaddrinfo failed'), <traceback object at 0x000001D178C881C0>)
Traceback (most recent call last):
  File "C:\Users\razie\DevOps\DomainMonitoringProject\domain-monitoring-project\domains_check_MT.py", line 61, in check_certificate
    with socket.create_connection((hostname, 443),timeout=5) as sock:
         ^^^^^^^^^^^^^^^^^^^^^^^^^^^^^^^^^^^^^^^^^^^^^^^^^^^
  File "C:\Users\razie\AppData\Local\Programs\Python\Python312\Lib\socket.py", line 841, in create_connection
    for res in getaddrinfo(host, port, 0, SOCK_STREAM):
               ^^^^^^^^^^^^^^^^^^^^^^^^^^^^^^^^^^^^^^^
  File "C:\Users\razie\AppData\Local\Programs\Python\Python312\Lib\socket.py", line 976, in getaddrinfo
    for res in _socket.getaddrinfo(host, port, family, type, proto, flags):
               ^^^^^^^^^^^^^^^^^^^^^^^^^^^^^^^^^^^^^^^^^^^^^^^^^^^^^^^^^^^
socket.gaierror: [Errno 11001] getaddrinfo failed
2024-11-26 14:07:15 - ERROR - [domains_check_MT.py:44] - Request error for miit.gov.cn: HTTPConnectionPool(host='miit.gov.cn', port=80): Max retries exceeded with url: / (Caused by NameResolutionError("<urllib3.connection.HTTPConnection object at 0x000001D17A24D280>: Failed to resolve 'miit.gov.cn' ([Errno 11001] getaddrinfo failed)"))
None
2024-11-26 14:07:15 - ERROR - [domains_check_MT.py:44] - Request error for nih.gov: ('Connection aborted.', RemoteDisconnected('Remote end closed connection without response'))
None
2024-11-26 14:07:17 - ERROR - [domains_check_MT.py:71] - SSL Error with vk.com: [SSL: CERTIFICATE_VERIFY_FAILED] certificate verify failed: self-signed certificate in certificate chain (_ssl.c:1000)
(<class 'ssl.SSLCertVerificationError'>, SSLCertVerificationError(1, '[SSL: CERTIFICATE_VERIFY_FAILED] certificate verify failed: self-signed certificate in certificate chain (_ssl.c:1000)'), <traceback object at 0x000001D17A6B5740>)
Traceback (most recent call last):
  File "C:\Users\razie\DevOps\DomainMonitoringProject\domain-monitoring-project\domains_check_MT.py", line 62, in check_certificate
    with context.wrap_socket(sock, server_hostname=hostname) as ssock:
         ^^^^^^^^^^^^^^^^^^^^^^^^^^^^^^^^^^^^^^^^^^^^^^^^^^^
  File "C:\Users\razie\AppData\Local\Programs\Python\Python312\Lib\ssl.py", line 455, in wrap_socket
    return self.sslsocket_class._create(
           ^^^^^^^^^^^^^^^^^^^^^^^^^^^^^
  File "C:\Users\razie\AppData\Local\Programs\Python\Python312\Lib\ssl.py", line 1041, in _create
    self.do_handshake()
  File "C:\Users\razie\AppData\Local\Programs\Python\Python312\Lib\ssl.py", line 1319, in do_handshake
    self._sslobj.do_handshake()
ssl.SSLCertVerificationError: [SSL: CERTIFICATE_VERIFY_FAILED] certificate verify failed: self-signed certificate in certificate chain (_ssl.c:1000)
2024-11-26 14:07:17 - ERROR - [domains_check_MT.py:71] - SSL Error with wixsite.com: [Errno 11001] getaddrinfo failed
(<class 'socket.gaierror'>, gaierror(11001, 'getaddrinfo failed'), <traceback object at 0x000001D17A292B00>)
Traceback (most recent call last):
  File "C:\Users\razie\DevOps\DomainMonitoringProject\domain-monitoring-project\domains_check_MT.py", line 61, in check_certificate
    with socket.create_connection((hostname, 443),timeout=5) as sock:
         ^^^^^^^^^^^^^^^^^^^^^^^^^^^^^^^^^^^^^^^^^^^^^^^^^^^
  File "C:\Users\razie\AppData\Local\Programs\Python\Python312\Lib\socket.py", line 841, in create_connection
    for res in getaddrinfo(host, port, 0, SOCK_STREAM):
               ^^^^^^^^^^^^^^^^^^^^^^^^^^^^^^^^^^^^^^^
  File "C:\Users\razie\AppData\Local\Programs\Python\Python312\Lib\socket.py", line 976, in getaddrinfo
    for res in _socket.getaddrinfo(host, port, family, type, proto, flags):
               ^^^^^^^^^^^^^^^^^^^^^^^^^^^^^^^^^^^^^^^^^^^^^^^^^^^^^^^^^^^
socket.gaierror: [Errno 11001] getaddrinfo failed
2024-11-26 14:07:17 - ERROR - [domains_check_MT.py:44] - Request error for wixsite.com: HTTPConnectionPool(host='wixsite.com', port=80): Max retries exceeded with url: / (Caused by NameResolutionError("<urllib3.connection.HTTPConnection object at 0x000001D17A660DD0>: Failed to resolve 'wixsite.com' ([Errno 11001] getaddrinfo failed)"))
None
2024-11-26 14:07:17 - ERROR - [domains_check_MT.py:71] - SSL Error with youtube-nocookie.com: [SSL: CERTIFICATE_VERIFY_FAILED] certificate verify failed: Hostname mismatch, certificate is not valid for 'youtube-nocookie.com'. (_ssl.c:1000)
(<class 'ssl.SSLCertVerificationError'>, SSLCertVerificationError(1, "[SSL: CERTIFICATE_VERIFY_FAILED] certificate verify failed: Hostname mismatch, certificate is not valid for 'youtube-nocookie.com'. (_ssl.c:1000)"), <traceback object at 0x000001D17A6F7B80>)
Traceback (most recent call last):
  File "C:\Users\razie\DevOps\DomainMonitoringProject\domain-monitoring-project\domains_check_MT.py", line 62, in check_certificate
    with context.wrap_socket(sock, server_hostname=hostname) as ssock:
         ^^^^^^^^^^^^^^^^^^^^^^^^^^^^^^^^^^^^^^^^^^^^^^^^^^^
  File "C:\Users\razie\AppData\Local\Programs\Python\Python312\Lib\ssl.py", line 455, in wrap_socket
    return self.sslsocket_class._create(
           ^^^^^^^^^^^^^^^^^^^^^^^^^^^^^
  File "C:\Users\razie\AppData\Local\Programs\Python\Python312\Lib\ssl.py", line 1041, in _create
    self.do_handshake()
  File "C:\Users\razie\AppData\Local\Programs\Python\Python312\Lib\ssl.py", line 1319, in do_handshake
    self._sslobj.do_handshake()
ssl.SSLCertVerificationError: [SSL: CERTIFICATE_VERIFY_FAILED] certificate verify failed: Hostname mismatch, certificate is not valid for 'youtube-nocookie.com'. (_ssl.c:1000)
2024-11-26 14:07:18 - ERROR - [domains_check_MT.py:44] - Request error for youtube-nocookie.com: HTTPSConnectionPool(host='youtube-nocookie.com', port=443): Max retries exceeded with url: / (Caused by SSLError(SSLCertVerificationError(1, "[SSL: CERTIFICATE_VERIFY_FAILED] certificate verify failed: Hostname mismatch, certificate is not valid for 'youtube-nocookie.com'. (_ssl.c:1000)")))
None
2024-11-26 14:07:19 - ERROR - [domains_check_MT.py:71] - SSL Error with macromedia.com: timed out
(<class 'TimeoutError'>, TimeoutError('timed out'), <traceback object at 0x000001D17A6F4980>)
Traceback (most recent call last):
  File "C:\Users\razie\DevOps\DomainMonitoringProject\domain-monitoring-project\domains_check_MT.py", line 61, in check_certificate
    with socket.create_connection((hostname, 443),timeout=5) as sock:
         ^^^^^^^^^^^^^^^^^^^^^^^^^^^^^^^^^^^^^^^^^^^^^^^^^^^
  File "C:\Users\razie\AppData\Local\Programs\Python\Python312\Lib\socket.py", line 865, in create_connection
    raise exceptions[0]
  File "C:\Users\razie\AppData\Local\Programs\Python\Python312\Lib\socket.py", line 850, in create_connection
    sock.connect(sa)
TimeoutError: timed out
2024-11-26 14:07:20 - ERROR - [domains_check_MT.py:44] - Request error for macromedia.com: HTTPConnectionPool(host='macromedia.com', port=80): Max retries exceeded with url: / (Caused by ConnectTimeoutError(<urllib3.connection.HTTPConnection object at 0x000001D17A715FA0>, 'Connection to macromedia.com timed out. (connect timeout=1)'))
None
2024-11-26 14:07:23 - ERROR - [domains_check_MT.py:71] - SSL Error with amazonaws.com: [WinError 10061] No connection could be made because the target machine actively refused it
(<class 'ConnectionRefusedError'>, ConnectionRefusedError(10061, 'No connection could be made because the target machine actively refused it', None, 10061, None), <traceback object at 0x000001D178C39080>)
Traceback (most recent call last):
  File "C:\Users\razie\DevOps\DomainMonitoringProject\domain-monitoring-project\domains_check_MT.py", line 61, in check_certificate
    with socket.create_connection((hostname, 443),timeout=5) as sock:
         ^^^^^^^^^^^^^^^^^^^^^^^^^^^^^^^^^^^^^^^^^^^^^^^^^^^
  File "C:\Users\razie\AppData\Local\Programs\Python\Python312\Lib\socket.py", line 865, in create_connection
    raise exceptions[0]
  File "C:\Users\razie\AppData\Local\Programs\Python\Python312\Lib\socket.py", line 850, in create_connection
    sock.connect(sa)
ConnectionRefusedError: [WinError 10061] No connection could be made because the target machine actively refused it
